Workbook

Sheet Легенда
A1: Каталог правил ИИ-проверки раздела 2 НД — АО «Озенмунайгаз»
A2: Категории: Земляные работы, Грузоподъемные работы, Работа в замкнутом пространстве, Другие работы повышенной опасности, Огневые работы, Газоопасные работы, Работы на высоте
A4: Порядок применения | B4: 1) Синтаксис (S01–S17). 2) Неприменимость (N01–N14). 3) Матрица пунктов по категории. 4) Правила категорий. 5) Оценка рисков (RA01–RA23) по справочнику опасностей и мер. 6) LLM — только для того, что код не решил.
A5: Листы | B5: «Синтаксис», «Неприменимость», «Пункты по категориям» (матрица 7 × 10), «Правила категорий», «Риски — обязательные», «Факторы», «Словарь маркеров», «Стоп-словарь», «Параметры», «Источники», «Сводка».
A6: Статусы пунктов | B6: Ядро — обязателен всегда, прочерк недопустим (N06). Условное — обязателен при факторе = Да; при факторе = Нет — прочерк, а выбранная запись даёт N02; при неизвестном факторе — вопрос (N14).
A7: Критичность | B7: Критично — блокирует отправку на согласование. Существенно — принять или отклонить с комментарием. Рекомендация — информационно. Вопрос — ответ сохраняется как значение фактора.
A8: Связь со справочниками БД | B8: Правила ссылаются на пункт 5.x и ключевые элементы, а не на ID записей. Для каждой записи справочника ОМГ в БД нужно проставить: категорию, пункт, тип (Ядро/Условное/Опциональное/Шаблон), факторы и ключевые элементы — по образцу файла разметки для ГПР и высоты.
A9: Допущение | B9: Форма раздела 5 (пп. 5.1–5.10 и их подсказки) одинакова для всех категорий РПО, как на экране ОМГ. Если у категории своя форма, матрицу нужно пересобрать.
A10: Статус оснований | B10: «Сверено» — пункт прочитан в тексте НПА РК. «Сверить» / «наполнить» / «решение ОМГ» — требуется подтверждение HSE-эксперта до включения критичности.

Sheet Сводка
A1: Категория | B1: Ядро | C1: Условные | D1: Правил категории | E1: Обязательных опасностей
A2: Земляные работы | B2: =COUNTIFS('Пункты по категориям'!$B:$B,A2,'Пункты по категориям'!$E:$E,"Ядро") -> 3 | C2: =COUNTIFS('Пункты по категориям'!$B:$B,A2,'Пункты по категориям'!$E:$E,"Условное") -> 7 | D2: =COUNTIF('Правила категорий'!$B:$B,A2) -> 7 | E2: =COUNTIF('Опасности по категориям'!$A:$A,A2) -> 5
A3: Грузоподъемные работы | B3: =COUNTIFS('Пункты по категориям'!$B:$B,A3,'Пункты по категориям'!$E:$E,"Ядро") -> 5 | C3: =COUNTIFS('Пункты по категориям'!$B:$B,A3,'Пункты по категориям'!$E:$E,"Условное") -> 5 | D3: =COUNTIF('Правила категорий'!$B:$B,A3) -> 5 | E3: =COUNTIF('Опасности по категориям'!$A:$A,A3) -> 5
A4: Работа в замкнутом пространстве | B4: =COUNTIFS('Пункты по категориям'!$B:$B,A4,'Пункты по категориям'!$E:$E,"Ядро") -> 8 | C4: =COUNTIFS('Пункты по категориям'!$B:$B,A4,'Пункты по категориям'!$E:$E,"Условное") -> 2 | D4: =COUNTIF('Правила категорий'!$B:$B,A4) -> 6 | E4: =COUNTIF('Опасности по категориям'!$A:$A,A4) -> 4
A5: Другие работы повышенной опасности | B5: =COUNTIFS('Пункты по категориям'!$B:$B,A5,'Пункты по категориям'!$E:$E,"Ядро") -> 2 | C5: =COUNTIFS('Пункты по категориям'!$B:$B,A5,'Пункты по категориям'!$E:$E,"Условное") -> 8 | D5: =COUNTIF('Правила категорий'!$B:$B,A5) -> 4 | E5: =COUNTIF('Опасности по категориям'!$A:$A,A5) -> 1
A6: Огневые работы | B6: =COUNTIFS('Пункты по категориям'!$B:$B,A6,'Пункты по категориям'!$E:$E,"Ядро") -> 6 | C6: =COUNTIFS('Пункты по категориям'!$B:$B,A6,'Пункты по категориям'!$E:$E,"Условное") -> 4 | D6: =COUNTIF('Правила категорий'!$B:$B,A6) -> 6 | E6: =COUNTIF('Опасности по категориям'!$A:$A,A6) -> 4
A7: Газоопасные работы | B7: =COUNTIFS('Пункты по категориям'!$B:$B,A7,'Пункты по категориям'!$E:$E,"Ядро") -> 8 | C7: =COUNTIFS('Пункты по категориям'!$B:$B,A7,'Пункты по категориям'!$E:$E,"Условное") -> 2 | D7: =COUNTIF('Правила категорий'!$B:$B,A7) -> 5 | E7: =COUNTIF('Опасности по категориям'!$A:$A,A7) -> 3
A8: Работы на высоте | B8: =COUNTIFS('Пункты по категориям'!$B:$B,A8,'Пункты по категориям'!$E:$E,"Ядро") -> 5 | C8: =COUNTIFS('Пункты по категориям'!$B:$B,A8,'Пункты по категориям'!$E:$E,"Условное") -> 5 | D8: =COUNTIF('Правила категорий'!$B:$B,A8) -> 8 | E8: =COUNTIF('Опасности по категориям'!$A:$A,A8) -> 4
A10: Правил синтаксиса (все категории) | B10: =COUNTA(Синтаксис!$A:$A)-1 -> 17
A11: Правил неприменимости (все категории) | B11: =COUNTA(Неприменимость!$A:$A)-1 -> 14
A12: Правил оценки рисков (все категории) | B12: =COUNTA('Оценка рисков — правила'!$A:$A)-1 -> 25

Sheet Синтаксис
A1: ID | B1: Проверка | C1: Описание | D1: Алгоритм / regex | E1: Критичность | F1: Сообщение пользователю | G1: Основание | H1: Примечание
A2: S01 | B2: Пустой пункт | C2: Значение пустое или только пробелы (прочерк не поставлен) | D2: trim(value)=='' | E2: Критично | F2: Пункт 5.x не заполнен. Если мероприятие не требуется — поставьте прочерк «—», иначе опишите мероприятие. | G2: № 344: в графах, не требующих заполнения, ставится прочерк
A3: S02 | B3: Заглушка | C3: Тестовое или бессмысленное значение | D3: regex (без учёта регистра, после trim): ^(test\w*|тест\w*|asdf\w*|qwe\w*|йцук\w*|xxx+|ххх+|ааа+|zzz+|1+|123\w*|0+|\.+|\?+|!+|,+|\++|=+|_+|ok|ок|да|нет\s*данных|не\s*знаю|todo|tbd|\*+)$ ; либо один символ, повторённый ≥3 раз (^(.)\1{2,}$) | E3: Критично | F3: В пункте 5.x указано тестовое значение «{value}». Опишите мероприятие или поставьте прочерк, если оно не требуется. | G3: № 344: заполнение по подстрочному тексту
A4: S03 | B4: Повтор подсказки поля | C4: Текст совпадает с подсказкой (подстрочным текстом) пункта | D4: normalize(value)==normalize(hint) или value является подстрокой hint длиной ≥ 70% hint | E4: Критично | F4: В пункт 5.x скопирована подсказка поля. Укажите конкретное мероприятие. | G4: № 344
A5: S04 | B5: Слишком короткий текст | C5: Менее 3 значимых слов (без предлогов и союзов) и не прочерк | D5: count(words, len≥3, not in stopwords) < 3 | E5: Существенно | F5: Мероприятие в пункте 5.x описано слишком кратко. Укажите, что сделать, где и кем. | G5: Практика заполнения НД | H5: Заменяет правило «менее 5 символов»
A6: S05 | B6: Нет букв / только цифры и символы | C6: Доля букв (кириллица, казахские, латиница) < 50% | D6: letters/len < 0.5 | E6: Критично | F6: Пункт 5.x не содержит текста мероприятия. | G6: № 344
A7: S06 | B7: Незаполненный шаблон | C7: Остались пропуски шаблона справочника | D7: regex: _{2,}|\[\s*\]|\{\s*\}|<\s*>|\.{3,}\s*$|…\s*$ | E7: Критично | F7: В шаблоне пункта 5.x не заполнены значения («___»). Укажите: {template_fields}. | G7: Разметка справочника (тип «Шаблон»)
A8: S07 | B8: Артефакты склейки справочника | C8: Двойная пунктуация и обрывки при склейке записей | D8: regex: \.;|;;|;\s*;|^\s*[;,.]|^\s*\S+;\s*[А-ЯЁ] (обрывок одного слова в начале, напр. «маршрут; Маршруты…»)|\s{2,} | E8: Рекомендация | F8: Исправлена пунктуация в пункте 5.x. | G8: — | H8: Автоисправление с показом пользователю
A9: S08 | B9: Незакрытые скобки и кавычки | C9: Непарные ( ) « » " " | D9: count('(')!=count(')') или count('«')!=count('»') или нечётное число '"' | E9: Рекомендация | F9: Проверьте скобки и кавычки в пункте 5.x. | G9: —
A10: S09 | B10: Смешение языков | C10: Казахские буквы в русском тексте (или наоборот при языке KK) | D10: lang(ui)=ru и regex [әғқңөұүһіӘҒҚҢӨҰҮҺІ] найден; для kk — доля русских слов из словаря > 50% (кроме терминов) | E10: Рекомендация | F10: В русском тексте пункта 5.x есть фрагмент на казахском языке — уберите или вынесите в казахскую версию. | G10: — | H10: Пример из справочника: «(ауысым алдындағы медтексеру)»
A11: S10 | B11: Латиница вместо кириллицы | C11: Латинские буквы-двойники внутри кириллических слов | D11: regex: [А-Яа-яЁё][AaBCcEeHKMOoPpTXxy]|[AaBCcEeHKMOoPpTXxy][А-Яа-яЁё] | E11: Рекомендация | F11: Исправлены символы в пункте 5.x. | G11: — | H11: Автоисправление; ломает поиск и сравнение со справочником
A12: S11 | B12: Дубль мероприятия | C12: Одинаковый текст в одном пункте или в разных пунктах | D12: normalize(a)==normalize(b) или similarity ≥ 0.95 | E12: Существенно | F12: Мероприятие «{short}» повторяется в пунктах {p1} и {p2}. Оставьте в одном, подходящем по смыслу. | G12: Разметка справочника
A13: S12 | B13: Повтор слова | C13: Одно слово подряд дважды | D13: regex: \b(\w+)\s+\1\b (без учёта регистра) | E13: Рекомендация | F13: Уберите повтор слова в пункте 5.x. | G13: — | H13: Автоисправление
A14: S13 | B14: Нормализация прочерка | C14: Варианты прочерка приводятся к «—» | D14: value in {'-','–','—','--','н/п','нп','не применимо','не требуется','не предусмотрено'} → '—'; «нет» без обоснования → need_input | E14: — | F14: — | G14: № 344 | H14: Служебное правило, результат используется правилами N07, N08
A15: S14 | B15: Число без единиц | C15: Числовое значение без единицы измерения там, где она обязательна | D15: regex: \b\d+([.,]\d+)?\b не followed by (м|мм|см|км|м/с|°C|°|кг|т|кВ|В|%|мг/м3|ppm|мин|ч|лк|шт|чел) в контексте слов «расстояние, высота, глубина, радиус, скорость, масса, напряжение, концентрация» | E15: Существенно | F15: Укажите единицы измерения для «{number}» в пункте 5.x. | G15: —
A16: S15 | B16: Недопустимые символы | C16: Emoji, HTML-теги, управляющие символы | D16: regex: <[^>]+>|[\u0000-\u0008\u000B\u000C\u000E-\u001F]|[\U0001F300-\U0001FAFF] | E16: Рекомендация | F16: Удалены недопустимые символы. | G16: — | H16: Автоисправление
A17: S16 | B17: Слишком длинная запись | C17: Одна запись > 1500 символов | D17: len(value) > 1500 | E17: Рекомендация | F17: Запись в пункте 5.x слишком длинная — разбейте на отдельные мероприятия. | G17: — | H17: Порог — параметр
A18: S17 | B18: Число вне здравого диапазона | C18: Известный параметр с неправдоподобным значением | D18: ветер > 60 м/с; угол > 90°; высота > 500 м; глубина > 30 м; расстояние > 10000 м; температура вне −60…+60 °C; концентрация > 100% | E18: Существенно | F18: Проверьте значение «{number}» в пункте 5.x. | G18: —

Sheet Неприменимость
A1: ID | B1: Проверка | C1: Описание | D1: Как определяется | E1: Критичность | F1: Сообщение пользователю | G1: Основание | H1: Пример
A2: N01 | B2: Маркеры другой категории | C2: В тексте есть маркеры группы, не разрешённой для категории и не включённой фактором | D2: Код: словарь маркеров (лист «Словарь маркеров»); LLM подтверждает при спорном случае | E2: Существенно | F2: Мероприятие «{short}» относится к {group} и, вероятно, не применимо к работе «{category}». Уточните или удалите. | G2: Разметка справочника | H2: Пример: краги сварщика в ГПР; тренога над горловиной ёмкости при предупреждении машинистов кранов
A3: N02 | B3: Условная запись при факторе = Нет | C3: Выбрана запись справочника, условие применимости которой не выполняется | D3: Код: catalog.applies_when ∩ factors | E3: Рекомендация | F3: Мероприятие применимо при условии «{factor}», а для этой работы оно не отмечено. Уточните или удалите. | G3: Разметка справочника
A4: N03 | B4: Сезонная неприменимость | C4: Меры для низких температур, обледенения, снега при датах работ в тёплый период — и наоборот (меры от жары зимой) | D4: Код: даты работ vs параметр «тёплый период ОМГ»; маркеры: мороз, обледенен, гололёд, снег, −20, −30, −40, ниже -N °C / жара, тепловой удар, +40 | E4: Рекомендация | F4: Мероприятие для {season} не соответствует датам работ {dates}. | G4: Параметр организации | H4: Не критично: лишняя мера не опасна, но засоряет НД
A5: N04 | B5: Объект отсутствует в организации | C5: Упоминается объект, которого нет в профиле организации/подразделения (ж/д пути в ОМГ, мостовой кран на промысле) | D5: Код: профиль подразделения (objects, F10 и т.п.) | E5: Рекомендация | F5: В профиле подразделения нет объекта «{object}». Подтвердите применимость мероприятия. | G5: Профиль ОМГ
A6: N05 | B6: Мероприятие не в своём пункте | C6: Содержание относится к другому пункту формы (газоанализ в 5.3, установка крана в 5.1) | D6: Код: классификатор пунктов по маркерам; LLM при неоднозначности | E6: Рекомендация | F6: Мероприятие «{short}» по смыслу относится к пункту {target}. Перенесите. | G6: Форма НД (подстрочный текст)
A7: N06 | B7: Прочерк в применимом пункте | C7: Прочерк или «не требуется» в пункте со статусом «Ядро» категории или при факторе = Да | D7: Код: матрица пунктов + факторы | E7: Критично | F7: Пункт 5.x обязателен для работы «{category}» — прочерк недопустим. Укажите мероприятие. | G7: № 344 + матрица категорий
A8: N07 | B8: Обоснование неприменимости противоречит данным | C8: «Не требуется» с обоснованием, которое противоречит факторам, описанию или рискам | D8: LLM: извлечение утверждения из обоснования + код: сверка с factors/risks | E8: Существенно | F8: Обоснование «{reason}» противоречит {conflict}. Проверьте пункт 5.x. | G8: Непротиворечивость НД | H8: Пример: «работ на высоте нет», а в рисках — падение с высоты
A9: N08 | B9: Оборудование не из описания работ | C9: Мероприятие относится к оборудованию, которого нет в описании работ и профиле | D9: LLM + код (словарь оборудования) | E9: Вопрос | F9: Мероприятие упоминает «{equipment}». Используется ли это оборудование в данной работе? | G9: — | H9: need_input, не замечание
A10: N09 | B10: Взаимоисключающие мероприятия | C10: Два мероприятия противоречат друг другу | D10: LLM (пары утверждений) | E10: Существенно | F10: Мероприятия «{a}» и «{b}» противоречат друг другу. Оставьте одно. | G10: Непротиворечивость НД | H10: Пример: «работы ведутся с земли» и «подъём в люльке автовышки»
A11: N10 | B11: Не подготовительное мероприятие | C11: Действия при аварии или по окончании работ внесены в раздел 5 | D11: Код: маркеры (при пожаре, при аварии, вызвать скорую, по окончании работ, сдать СИЗ, закрыть наряд) | E11: Рекомендация | F11: Действия «при аварии» / «по окончании работ» не относятся к подготовительным мероприятиям. | G11: Разметка справочника
A12: N11 | B12: Ссылка на нормы других государств | C12: Текст пользователя ссылается на НПА РФ и других государств | D12: Код: стоп-словарь (лист «Стоп-словарь») | E12: Существенно | F12: В пункте 5.x указана ссылка на документ, не действующий в РК: «{ref}». Замените ссылкой на НПА РК или стандарт организации. | G12: Требование применения НПА РК
A13: N12 | B13: Категория противоречит флагам раздела 2 | C13: Флаг не соответствует категории | D13: Код: газоопасные и замкнутое пространство → «Контроль ГВС» = Да; земляные → «Согласование со смежными» = Да; огневые → поле «Противопожарная служба» по параметру ОМГ | E13: Критично | F13: Для работы «{category}» флаг «{flag}» должен быть «{value}». | G13: № 344 (земляные — согласование); № 355 п. 33 (анализ среды)
A14: N13 | B14: Флаг противоречит тексту | C14: Флаг раздела 2 = Нет, а в тексте мероприятие по этому флагу (или наоборот) | D14: LLM (извлечение фактов) + код | E14: Критично | F14: Флаг «{flag}» = «{value}», но в пункте {p} указано: «{short}». Приведите в соответствие. | G14: Непротиворечивость НД | H14: Пример: ГВС = Нет, а в 5.4 непрерывный газовый контроль
A15: N14 | B15: Условие неизвестно | C15: Для условной записи фактор не определён | D15: Код | E15: Вопрос | F15: Уточните: {factor_question} | G15: — | H15: need_input

Sheet Пункты по категориям
A1: ID | B1: Категория | C1: Пункт | D1: Название пункта | E1: Статус | F1: Факторы (для условного) | G1: Минимальное содержание (ключевые элементы) | H1: Критичность при отсутствии | I1: Основание
A2: ZR-5.1 | B2: Земляные работы | C2: 5.1 | D2: Остановить | E2: Условное | F2: F12, F29 | G2: Остановка техники и оборудования в зоне выемки | H2: Существенно | I2: Справочник ОМГ
A3: ZR-5.2 | B3: Земляные работы | C3: 5.2 | D3: Отключить | E3: Условное | F3: F27, F09 | G3: Отключение кабелей в зоне работ; сброс давления в трубопроводах при вскрытии | H3: Критично | I3: № 344 (согласование с владельцами коммуникаций)
A4: ZR-5.3 | B4: Земляные работы | C4: 5.3 | D4: Установить (заглушки, тупики, сигнальные лампы) | E4: Условное | F4: F32 | G4: Заглушки при вскрытии трубопровода; сигнальные лампы на ограждении | H4: Существенно | I4: Справочник ОМГ
A5: ZR-5.4 | B5: Земляные работы | C5: 5.4 | D5: Взять пробу воздушной среды | E5: Условное | F5: F03 | G5: Анализ воздуха в траншее, шурфе, котловане до спуска людей: место, время, прибор, результат | H5: Критично | I5: № 355, п. 33 (траншеи, шурфы)
A6: ZR-5.5 | B6: Земляные работы | C6: 5.5 | D6: Оградить | E6: Ядро | G6: Ограждение выемки высотой не менее 1 м или защитное покрытие; знаки безопасности | H6: Критично | I6: № 355, пп. 28, 128
A7: ZR-5.6 | B7: Земляные работы | C7: 5.6 | D7: Меры при работе на высоте и в колодцах | E7: Условное | F7: F28 | G7: При глубине ≥ 1,3 м: ограждение бровки, лестницы для спуска и выхода, крепление стенок или откосы | H7: Критично | I7: № 109, п. 2 (высота или глубина ≥ 1,3 м) — трактовку подтвердить; параметры крепления — СН РК 1.03-05-2011 (сверить)
A8: ZR-5.7 | B8: Земляные работы | C8: 5.7 | D8: Предупредить | E8: Ядро | G8: Предупреждение/вызов представителей организаций — владельцев коммуникаций; согласование и схема коммуникаций | H8: Критично | I8: № 344 (все земляные работы согласуются, схемы прилагаются)
A9: ZR-5.8 | B9: Земляные работы | C9: 5.8 | D9: Меры у железнодорожных путей | E9: Условное | F9: F10 | G9: Меры у ж/д путей | H9: Существенно | I9: № 344
A10: ZR-5.9 | B10: Земляные работы | C10: 5.9 | D10: Маршруты к месту работы | E10: Ядро | G10: Маршрут к месту работ; проезды техники; выходы из выемки | H10: Существенно | I10: № 355, п. 30 (освещение подходов)
A11: ZR-5.10 | B11: Земляные работы | C11: 5.10 | D11: Дополнительные мероприятия | E11: Условное | F11: F29, F36 | G11: Разработка вручную в зоне коммуникаций; техника и отвал грунта не у бровки (параметр); работы в охранной зоне — по согласованию | H11: Существенно | I11: СН РК 1.03-05-2011 — сверить
A12: GP-5.1 | B12: Грузоподъемные работы | C12: 5.1 | D12: Остановить | E12: Условное | F12: F07, F11, F12 | G12: Остановка СК, других ГПМ и механизмов в зоне | H12: Существенно | I12: Справочник ОМГ
A13: GP-5.2 | B13: Грузоподъемные работы | C13: 5.2 | D13: Отключить | E13: Условное | F13: F02, F08, F09 | G13: При ВЛ ближе 30 м — отдельный НД/согласование; отключение электропривода; сброс давления | H13: Критично | I13: Правила ГПМ № 359 (сверить) + № 344
A14: GP-5.3 | B14: Грузоподъемные работы | C14: 5.3 | D14: Установить (заглушки, тупики, сигнальные лампы) | E14: Ядро | G14: Установка ГПМ на выносные опоры и подкладки; сигнальные лампы в тёмное время | H14: Критично | I14: Справочник ОМГ
A15: GP-5.4 | B15: Грузоподъемные работы | C15: 5.4 | D15: Взять пробу воздушной среды | E15: Условное | F15: F03 | G15: Анализ воздуха у устья/насосной до начала работ | H15: Критично | I15: № 355, п. 33
A16: GP-5.5 | B16: Грузоподъемные работы | C16: 5.5 | D16: Оградить | E16: Ядро | G16: Ограждение опасной зоны; запрет нахождения под грузом и стрелой; плакаты | H16: Критично | I16: № 355, п. 28
A17: GP-5.6 | B17: Грузоподъемные работы | C17: 5.6 | D17: Меры при работе на высоте и в колодцах | E17: Условное | F17: F05, F14 | G17: Страховка персонала на высоте; разделение работ на высоте и подъёма грузов | H17: Критично | I17: № 109, пп. 9, 80
A18: GP-5.7 | B18: Грузоподъемные работы | C18: 5.7 | D18: Предупредить | E18: Ядро | G18: Предупреждение машинистов смежных ГПМ, операторов, диспетчера; запись в журнале | H18: Существенно | I18: Справочник ОМГ
A19: GP-5.8 | B19: Грузоподъемные работы | C19: 5.8 | D19: Меры у железнодорожных путей | E19: Условное | F19: F10 | G19: Меры у ж/д путей | H19: Существенно | I19: № 344
A20: GP-5.9 | B20: Грузоподъемные работы | C20: 5.9 | D20: Маршруты к месту работы | E20: Ядро | G20: Маршруты персонала и техники; проходы к местам строповки | H20: Существенно | I20: Справочник ОМГ
A21: GP-5.10 | B21: Грузоподъемные работы | C21: 5.10 | D21: Дополнительные мероприятия | E21: Ядро | G21: Связь стропальщик – машинист – производитель; строповка по схеме; проверка ГЗП; стоп при ветре/грозе | H21: Существенно | I21: № 355, п. 39 + справочник
A22: ZP-5.1 | B22: Работа в замкнутом пространстве | C22: 5.1 | D22: Остановить | E22: Ядро | G22: Остановка оборудования, мешалок, насосов, связанных с ёмкостью | H22: Критично | I22: Справочник ОМГ (наполнить)
A23: ZP-5.2 | B23: Работа в замкнутом пространстве | C23: 5.2 | D23: Отключить | E23: Ядро | G23: Отключение электроприводов с плакатами; освобождение от продукта; сброс давления | H23: Критично | I23: Справочник ОМГ (наполнить)
A24: ZP-5.3 | B24: Работа в замкнутом пространстве | C24: 5.3 | D24: Установить (заглушки, тупики, сигнальные лампы) | E24: Ядро | G24: Заглушки на всех входящих трубопроводах | H24: Критично | I24: Справочник ОМГ (наполнить)
A25: ZP-5.4 | B25: Работа в замкнутом пространстве | C25: 5.4 | D25: Взять пробу воздушной среды | E25: Ядро | G25: Анализ воздуха внутри до входа и периодически: место, время, прибор, результат; остановка при загазованности | H25: Критично | I25: № 355, п. 33 (изолированные помещения, закрытые ёмкости, колодцы)
A26: ZP-5.5 | B26: Работа в замкнутом пространстве | C26: 5.5 | D26: Оградить | E26: Ядро | G26: Ограждение зоны у люка; знаки | H26: Существенно | I26: № 355, п. 28
A27: ZP-5.6 | B27: Работа в замкнутом пространстве | C27: 5.6 | D27: Меры при работе на высоте и в колодцах | E27: Условное | F27: F06, F16 | G27: Вертикальный вход/колодец: страховочная привязь с сигнально-спасательной верёвкой, средство подъёма | H27: Критично | I27: Стандарт ОМГ (сверить)
A28: ZP-5.7 | B28: Работа в замкнутом пространстве | C28: 5.7 | D28: Предупредить | E28: Ядро | G28: Предупреждение оператора/диспетчера о работе внутри ёмкости | H28: Существенно | I28: Справочник ОМГ
A29: ZP-5.8 | B29: Работа в замкнутом пространстве | C29: 5.8 | D29: Меры у железнодорожных путей | E29: Условное | F29: F10 | G29: Меры у ж/д путей | H29: Существенно | I29: № 344
A30: ZP-5.9 | B30: Работа в замкнутом пространстве | C30: 5.9 | D30: Маршруты к месту работы | E30: Ядро | G30: Маршрут эвакуации из ёмкости и с площадки | H30: Существенно | I30: Справочник ОМГ
A31: ZP-5.10 | B31: Работа в замкнутом пространстве | C31: 5.10 | D31: Дополнительные мероприятия | E31: Ядро | G31: Наблюдающий снаружи; связь; СИЗОД по стандарту ОМГ; вентиляция; взрывозащищённое освещение и инструмент | H31: Критично | I31: Стандарт ОМГ (сверить)
A32: DR-5.1 | B32: Другие работы повышенной опасности | C32: 5.1 | D32: Остановить | E32: Условное | F32: по описанию | G32: Определяется по описанию работ (LLM) и справочнику категории | H32: Существенно | I32: Справочник ОМГ
A33: DR-5.2 | B33: Другие работы повышенной опасности | C33: 5.2 | D33: Отключить | E33: Условное | F33: по описанию | G33: Определяется по описанию работ (LLM) и справочнику категории | H33: Существенно | I33: Справочник ОМГ
A34: DR-5.3 | B34: Другие работы повышенной опасности | C34: 5.3 | D34: Установить (заглушки, тупики, сигнальные лампы) | E34: Условное | F34: по описанию | G34: Определяется по описанию работ (LLM) и справочнику категории | H34: Существенно | I34: Справочник ОМГ
A35: DR-5.4 | B35: Другие работы повышенной опасности | C35: 5.4 | D35: Взять пробу воздушной среды | E35: Условное | F35: по описанию | G35: Определяется по описанию работ (LLM) и справочнику категории | H35: Существенно | I35: Справочник ОМГ
A36: DR-5.5 | B36: Другие работы повышенной опасности | C36: 5.5 | D36: Оградить | E36: Ядро | G36: Ограждение или обозначение опасного участка | H36: Критично | I36: № 355, п. 28
A37: DR-5.6 | B37: Другие работы повышенной опасности | C37: 5.6 | D37: Меры при работе на высоте и в колодцах | E37: Условное | F37: по описанию | G37: Определяется по описанию работ (LLM) и справочнику категории | H37: Существенно | I37: Справочник ОМГ
A38: DR-5.7 | B38: Другие работы повышенной опасности | C38: 5.7 | D38: Предупредить | E38: Условное | F38: по описанию | G38: Определяется по описанию работ (LLM) и справочнику категории | H38: Существенно | I38: Справочник ОМГ
A39: DR-5.8 | B39: Другие работы повышенной опасности | C39: 5.8 | D39: Меры у железнодорожных путей | E39: Условное | F39: по описанию | G39: Определяется по описанию работ (LLM) и справочнику категории | H39: Существенно | I39: Справочник ОМГ
A40: DR-5.9 | B40: Другие работы повышенной опасности | C40: 5.9 | D40: Маршруты к месту работы | E40: Ядро | G40: Маршрут к месту работ | H40: Существенно | I40: Справочник ОМГ
...

Sheet Правила категорий
A1: ID | B1: Категория | C1: Проверка | D1: Исполнитель | E1: Критичность | F1: Основание
A2: ZR-01 | B2: Земляные работы | C2: Флаг «Согласование со смежными цехами/участками» = Да; в 5.7 указано согласование с владельцами коммуникаций | D2: Код | E2: Критично | F2: № 344: все земляные работы предварительно согласуются с обслуживающими организациями
A3: ZR-02 | B3: Земляные работы | C3: Есть ссылка на схему коммуникаций во вложениях | D3: Код (вложения) | E3: Существенно | F3: № 344: схемы прилагаются к НД
A4: ZR-03 | B4: Земляные работы | C4: Ограждение выемки ≥ 1 м или защитное покрытие | D4: Код + LLM | E4: Критично | F4: № 355, п. 128
A5: ZR-04 | B5: Земляные работы | C5: При F03 или шурфе/траншее на объекте с газом — анализ воздуха до спуска людей | D5: Код | E5: Критично | F5: № 355, п. 33
A6: ZR-05 | B6: Земляные работы | C6: При глубине сверх допустимой без крепления — крепление стенок или откосы | D6: Код (параметр) + LLM | E6: Критично | F6: СН РК 1.03-05-2011 — сверить пороги
A7: ZR-06 | B7: Земляные работы | C7: При F27 — ручная разработка в зоне коммуникаций, присутствие представителя владельца | D7: LLM | E7: Критично | F7: Практика + стандарт ОМГ — сверить
A8: ZR-07 | B8: Земляные работы | C8: Опасности «обрушение грунта», «повреждение коммуникаций» есть в рисках | D8: Код | E8: Существенно | F8: Справочник рисков
A9: GP-01 | B9: Грузоподъемные работы | C9: ВЛ ближе 30 м (F02) → флаг согласования = Да и отдельный НД | D9: Код | E9: Критично | F9: Правила ГПМ № 359 — сверить пункт; № 344
A10: GP-02 | B10: Грузоподъемные работы | C10: Запрет нахождения под грузом и стрелой указан | D10: Код + LLM | E10: Критично | F10: Справочник ОМГ
A11: GP-03 | B11: Грузоподъемные работы | C11: Совмещение с работой на высоте (F05) → разделение по времени | D11: Код | E11: Критично | F11: № 109, п. 80
A12: GP-04 | B12: Грузоподъемные работы | C12: Связь стропальщик – машинист – производитель | D12: Код + LLM | E12: Существенно | F12: № 355, п. 39
... A42: VS-08 | B42: Работы на высоте | C42: Предметы > 10 кг — независимая страховка (при F25) | D42: Код | E42: Существенно | F42: № 109, п. 85

Sheet Оценка рисков — правила
A1: ID | B1: Группа | C1: Проверка | D1: Исполнитель | E1: Критичность | F1: Сообщение пользователю | G1: Основание
A2: RA01 | B2: Полнота | C2: Таблица рисков пустая | D2: Код | E2: Критично | F2: Оценка рисков не заполнена. Добавьте опасности для работы «{category}».
A3: RA02 | B3: Полнота | C3: В строке не заполнено обязательное поле: опасность, кто может пострадать, как, существующие меры, В, П | D3: Код | E3: Критично | F3: Строка {n}: не заполнено поле «{field}».
A4: RA03 | B4: Арифметика | C4: В или П вне шкалы организации (целое в диапазоне P10) | D4: Код | E4: Критично | F4: Строка {n}: значение {field} = {value} вне шкалы {min}–{max}. | G4: Параметр P10
A5: RA04 | B5: Арифметика | C5: Р ≠ В × П (исходный или остаточный). Р рассчитывается системой, ручной ввод запрещён | D5: Код (автоисправление) | E5: Критично | F5: Строка {n}: Р пересчитан: {B} × {P} = {R}.
A6: RA05 | B6: Логика снижения | C6: Остаточный Р больше исходного | D6: Код | E6: Критично | F6: Строка {n}: остаточный риск ({R2}) выше исходного ({R1}).
A7: RA06 | B7: Логика снижения | C7: Остаточные В/П заполнены и ниже исходных, а доп. меры пусты | D7: Код | E7: Критично | F7: Строка {n}: риск снижен без дополнительных мер. Укажите меры или верните исходные значения.
A8: RA07 | B8: Логика снижения | C8: Доп. меры заполнены, а остаточные В/П не указаны | D8: Код | E8: Существенно | F8: Строка {n}: укажите остаточные В и П после доп. мер.
A9: RA08 | B9: Логика снижения | C9: Доп. меры совпадают с существующими (тот же ID справочника или сходство ≥ 0,9) | D9: Код | E9: Критично | F9: Строка {n}: доп. мера «{m}» уже указана в существующих мерах и не может снижать риск повторно.
A10: RA09 | B10: Логика снижения | C10: Снижена тяжесть В, но ни одна доп. мера не влияет на тяжесть (признак меры «влияет на» = П) | D10: Код (по признаку меры); LLM, если признак не задан | E10: Существенно | F10: Строка {n}: тяжесть снижена с {B1} до {B2}, но меры «{m}» влияют только на вероятность. | G10: Иерархия мер
A11: RA10 | B11: Допустимость | C11: Остаточный Р в недопустимой зоне организации | D11: Код (параметр P10) | E11: Критично | F11: Строка {n}: остаточный риск {R2} недопустим. Нужны дополнительные меры или решение руководства. | G11: Параметр P10
A12: RA11 | B12: Допустимость | C12: Исходный Р в зоне «требует мер», а доп. меры не указаны | D12: Код (параметр P10) | E12: Существенно | F12: Строка {n}: риск {R1} требует дополнительных мер контроля. | G12: Параметр P10
A13: RA12 | B13: Состав | C13: Отсутствует обязательная опасность категории (лист «Опасности по категориям», когда = Всегда) | D13: Код | E13: По справочнику | F13: Для работы «{category}» не оценена опасность «{hazard}». | G13: Справочник опасностей
A14: RA13 | B14: Состав | C14: Отсутствует опасность, обязательная при подтверждённом факторе | D14: Код | E14: Существенно | F14: Фактор «{factor}» = Да, но опасность «{hazard}» не оценена. | G14: Справочник опасностей
A15: RA14 | B15: Состав | C15: Одна и та же опасность повторяется с тем же «кто» и «как» | D15: Код | E15: Существенно | F15: Строки {n1} и {n2} дублируют друг друга.
A16: RA15 | B16: Применимость | C16: Опасность из справочника другой категории без соответствующего фактора | D16: Код | E16: Рекомендация | F16: Опасность «{hazard}» не характерна для работы «{category}». Уточните применимость. | G16: Аналог N01
A17: RA16 | B17: Согласованность | C17: «Кто пострадает» / «как пострадает» не связаны с опасностью в справочнике | D17: Код (связи справочника); LLM, если связей нет | E17: Существенно | F17: Строка {n}: «{harm}» не соответствует опасности «{hazard}».
A18: RA17 | B18: Согласованность | C18: Существующая или доп. мера не связана с опасностью | D18: Код (связи справочника); LLM, если связей нет | E18: Существенно | F18: Строка {n}: мера «{m}» не снижает опасность «{hazard}».
A19: RA18 | B19: Связь с разделом 5 | C19: Для опасности с Р ≥ порога нет мероприятия в связанном пункте 5.x | D19: Код | E19: Существенно | F19: Для опасности «{hazard}» нет мероприятия в пункте {section}.
A20: RA19 | B20: Связь с разделом 5 | C20: Мероприятие раздела 5 указывает на опасность (ЛЭП, газ, высота, коммуникации), которой нет в рисках | D20: Код (маркеры) + LLM | E20: Существенно | F20: В пункте {section} есть мероприятие по «{topic}», но соответствующая опасность не оценена.
A21: RA20 | B21: Связь с разделом 5 | C21: Доп. мера контроля не отражена в мероприятиях раздела 5 (не будет выполнена при подготовке) | D21: Код (связь меры с пунктом) + LLM | E21: Рекомендация | F21: Доп. мера «{m}» отсутствует в подготовительных мероприятиях. Добавьте её в пункт {section}.
A22: RA21 | B22: Достоверность | C22: Тяжесть ниже минимальной для опасности (признак справочника «мин. тяжесть») | D22: Код (параметр шкалы) | E22: Существенно | F22: Строка {n}: тяжесть «{hazard}» = {B}, минимально допустимая для этой опасности — {Bmin}. | G22: Справочник опасностей
A23: RA22 | B23: Достоверность | C23: Все строки с одинаковыми В и П (шаблонное заполнение) | D23: Код | E23: Вопрос | F23: Все опасности оценены одинаково ({B} × {P}). Подтвердите оценку.
A24: RA23 | B24: Иерархия мер | C24: При исходном Р в зоне «высокий» все доп. меры — только СИЗ и организационные | D24: Код (уровень иерархии меры); LLM, если не задан | E24: Рекомендация | F24: Строка {n}: для высокого риска рассмотрите инженерные меры или замену способа работ. | G24: Иерархия мер
A25: RA24 | B25: Полнота | C25: Заполнены доп. меры, а «Кто будет контролировать» или «Когда внедрить» пусты | D25: Код | E25: Существенно | F25: Строка {n}: укажите, кто контролирует доп. меры и когда их внедрить.
A26: RA25 | B26: Допустимость | C26: «Когда внедрить» позже начала работ для доп. меры, без которой исходный риск в недопустимой зоне | D26: Код (параметр P10) | E26: Критично | F26: Строка {n}: мера «{m}» должна быть внедрена до начала работ — без неё риск {R1} недопустим. | G26: Параметр P10

Sheet Опасности по категориям
A1: Категория | B1: Опасность | C1: Обязательна | D1: Мин. тяжесть | E1: Кто может пострадать | F1: Как пострадают | G1: Типовые существующие меры | H1: Типовые доп. меры (уровень / влияет на) | I1: Связанные пп. 5.x | J1: Критичность при отсутствии
A2: Земляные работы | B2: Обрушение грунта стенок выемки | C2: Всегда | D2: Высокая | E2: Работники в выемке | F2: Завал, травмы, удушье | G2: Откосы по проекту; крепление стенок | H2: Инспекция крепления перед сменой (орг. / П); запрет нахождения в выемке без крепления (орг. / П) | I2: 5.6, 5.10 | J2: Критично
A3: Земляные работы | B3: Повреждение подземных коммуникаций | C3: F27 | D3: Высокая | E3: Бригада, машинист техники | F3: Поражение током, выброс газа/нефти, пожар | G3: Схема коммуникаций; согласование с владельцами | H3: Ручная разработка в зоне коммуникаций (орг. / П); шурфование (инж. / П); отключение кабеля (инж. / П+В) | I3: 5.2, 5.7 | J3: Критично
A4: Земляные работы | B4: Падение в выемку | C4: Всегда | D4: Средняя | E4: Работники, посторонние | F4: Переломы, ушибы | G4: Ограждение ≥ 1 м | H4: Освещение в тёмное время (инж. / П); переходные мостики (инж. / П) | I4: 5.5 | J4: Существенно
A5: Земляные работы | B5: Загазованность выемки | C5: F03 | D5: Высокая | E5: Работники в выемке | F5: Отравление, потеря сознания | G5: Анализ воздуха до спуска | H5: Непрерывный газоконтроль (инж. / П); СИЗОД (СИЗ / В) | I5: 5.4 | J5: Критично
A6: Земляные работы | B6: Наезд / удар техникой | C6: F29 | D6: Высокая | E6: Работники у техники | F6: Травмы | G6: Сигнальщик; зона работы техники | H6: Запрет нахождения в радиусе действия ковша (орг. / П) | I6: 5.1, 5.9 | J6: Существенно
A7: Грузоподъемные работы | B7: Падение груза | C7: Всегда | D7: Высокая | E7: Стропальщики, бригада | F7: Травмы, смертельный исход | G7: Строповка по схеме; исправные стропы | H7: Пробный подъём 200–300 мм (орг. / П); ограждение опасной зоны (инж. / П) | I7: 5.5, 5.10 | J7: Критично
A8: Грузоподъемные работы | B8: Опрокидывание ГПМ | C8: Всегда | D8: Высокая | E8: Машинист, бригада | F8: Травмы, смертельный исход | G8: Установка на выносные опоры и подкладки | H8: Проверка грунта (орг. / П); ограничитель грузоподъёмности (инж. / П) | I8: 5.3 | J8: Критично
A9: Грузоподъемные работы | B9: Поражение током при приближении к ВЛ | C9: F02 | D9: Высокая | E9: Машинист, стропальщики | F9: Электротравма | G9: Отдельный НД; согласование с сетевой организацией | H9: Снятие напряжения с ВЛ (устр. / П+В); ограничитель зоны работы (инж. / П) | I9: 5.2 | J9: Критично
A10: Грузоподъемные работы | B10: Защемление, удар грузом | C10: Всегда | D10: Средняя | E10: Стропальщики | F10: Травмы рук, ушибы | G10: Оттяжки | H10: Запрет направлять груз руками (орг. / П) | I10: 5.5 | J10: Существенно
A11: Грузоподъемные работы | B11: Нарушение связи и сигнализации | C11: Всегда | D11: Средняя | E11: Бригада | F11: Падение груза, удар | G11: Знаковая сигнализация | H11: Двусторонняя радиосвязь (инж. / П) | I11: 5.10 | J11: Существенно
A12: Работа в замкнутом пространстве | B12: Отравление / удушье | C12: Всегда | D12: Высокая | E12: Работник внутри, спасатели | F12: Потеря сознания, смертельный исход | G12: Анализ воздуха до входа; вентиляция | H12: Непрерывный газоконтроль (инж. / П); изолирующий СИЗОД (СИЗ / В); наблюдающий (орг. / В) | I12: 5.4, 5.10 | J12: Критично
... A27: Другие работы повышенной опасности | B27: ≥ 1 опасность по описанию работ | C27: Всегда | D27: По описанию | E27: По описанию | F27: По описанию | G27: — | H27: — | I27: по описанию | J27: Критично

Sheet Разметка рисков в БД
A1: Справочник | B1: Поле | C1: Значения | D1: Используется в правилах
A2: Опасность | B2: Категории | C2: список категорий | D2: RA12, RA15
A3: Опасность | B3: Обязательность | C3: Всегда / по фактору / нет | D3: RA12, RA13
A4: Опасность | B4: Факторы | C4: коды F.. | D4: RA13
A5: Опасность | B5: Мин. тяжесть | C5: уровень: высокая / средняя / низкая → значение по шкале ОМГ (параметр P13) | D5: RA21
A6: Опасность | B6: Допустимые «кто пострадает» | C6: ID справочника | D6: RA16
A7: Опасность | B7: Допустимые «как пострадают» | C7: ID справочника | D7: RA16
A8: Опасность | B8: Допустимые меры | C8: ID справочника мер | D8: RA17
A9: Опасность | B9: Связанные пункты 5.x | C9: 5.1…5.10 | D9: RA18
A10: Опасность | B10: Критичность при отсутствии | C10: Критично / Существенно | D10: RA12
A11: Мера контроля | B11: Уровень иерархии | C11: устранение / замена / инженерная / организационная / СИЗ | D11: RA23
A12: Мера контроля | B12: Влияет на | C12: П / В / П+В | D12: RA09
... A15: Мера контроля | B15: Категории | C15: список категорий, где мера применима | D15: RA15 (для мер)

Sheet Факторы
A1: Код | B1: Вопрос пользователю | C1: Категории | D1: Источник значения | E1: По умолчанию (ОМГ)
A2: F01 | B2: В зоне работ на высоте работают ГПМ / спецтехника? | C2: VS | D2: Пользователь | E2: —
A3: F02 | B3: ВЛ в радиусе 30 м от зоны работ / крана? | C3: Все | D3: Пользователь; профиль — «возможно» | E3: Спросить
A4: F03 | B4: Газоопасная зона (устье, насосная, колодец, ёмкость, траншея на объекте с газом)? | C4: Все | D4: Описание + профиль + пользователь | E4: Да для ЦДНГ, ЦППД (профиль)
A5: F04 | B5: Работы в тёмное время суток? | C5: Все | D5: Время работ (авто) | E5: По времени
A6: F05 | B6: Персонал на высоте ≥ 1,3 м при грузоподъёмных работах? | C6: GP | D6: Пользователь | E6: —
A7: F06 | B7: Спуск в колодец / вертикальный вход? | C7: ZP, GO, VS | D7: Пользователь | E7: —
A8: F07 | B8: Скважина со станком-качалкой? | C8: GP, VS | D8: Описание + пользователь | E8: —
A9: F08 | B9: Трубопроводы / оборудование под давлением в зоне? | C9: Все | D9: Профиль + пользователь | E9: Да для ЦДНГ, ЦППД
A10: F09 | B10: Электрооборудование в зоне? | C10: Все | D10: Профиль + пользователь | E10: Да для объектов промысла
A11: F10 | B11: Ж/д пути в зоне работ? | C11: Все | D11: Профиль организации | E11: Нет (ОМГ)
A12: F11 | B12: Тип ГПМ | C12: GP | D12: Пользователь | E12: —
... A28: F38 | B28: Одновременно несколько подрядных организаций на объекте? | C28: Все | D28: Пользователь | E28: —

Sheet Словарь маркеров
A1: Группа | B1: Маркеры (основы слов) | C1: Разрешено в категориях | D1: Разрешено при факторах
A2: Огневые | B2: сварк, электрод, огарк, искр, газорез, резак, резк, пропан, ацетилен, горелк, пламя, краги, термостойк | C2: OG | D2: F19, F31, F35
A3: Грузоподъёмные | B3: строп, кран, грузоподъ, аутригер, выносн опор, стрел, крюк, траверс, такелаж | C3: GP | D3: F01, F11, F12
A4: Высота | B4: страховочн, привязь, предохранительн пояс, карабин, анкер, люльк, автовышк, подмост, леса, стремянк, приставн лестниц | C4: VS | D4: F05, F06, F14, F16, F28
A5: Замкнутое пространство | B5: горловин, внутрь ёмкост, внутри аппарат, лаз, тренога, сигнально-спасательн, шлангов противогаз | C5: ZP | D5: F06, F31
A6: Газоопасные | B6: газоанализ, ПДК, НКПР, сероводород, H2S, СИЗОД, противогаз, загазован, продувк, дегазац | C6: GO, ZP | D6: F03 (допускается в любой категории при F03)
A7: Земляные | B7: траншея, котлован, шурф, откос, крепление стенок, бровк, экскаватор, отвал грунт | C7: ZR | D7: F27, F28
A8: Электроустановки | B8: проверка отсутствия напряжения, указатель напряжения, переносное заземление, диэлектрич | C8: (вид «Электроустановки») | D8: F09 (частично)
A9: Ж/д пути | B9: рельс, железнодорож, ж/д, дистанци пути, сигнальщик-маневров, башмак тормозн | C9: — | D9: F10
A10: Аварийные действия | B10: при пожаре, при аварии, вызвать скорую, эвакуировать пострадавш, первую помощь | C10: — | D10: — (N10)
A11: Окончание работ | B11: по окончании работ, после окончания, сдать СИЗ, закрыть наряд, убрать инструмент | C11: — | D11: — (N10)

Sheet Стоп-словарь
A1: Группа | B1: Значения | C1: Правило
A2: Заглушки | B2: test, тест, testtest, asdf, qwe, йцук, xxx, ххх, ааа, 123, ok, ок, «.», «?», «-» в ядре | C2: S02
A3: Нормы РФ | B3: Минтруда России, Минтруд РФ, Ростехнадзор, ФНП, ПОТ РО, СНиП 12-, приказ № 782н, 903н, 835н, 328н, 528, «Правила по охране труда при работе на высоте» (РФ), 15 календарных дней, 1,8 м | C3: N11
A4: Устаревшие формулировки справочника | B4: «нормы местных органов» (температура), «смежных пролётах» (цеховая терминология для промысла) | C4: VS-03, справочник

Sheet Параметры
A1: Код | B1: Параметр | C1: Значение | D1: Источник | E1: Статус
A2: P01 | B2: Порог работы на высоте | C2: 1,3 м (и < 2 м от перепада) | D2: № 109, п. 2 | E2: Сверено
A3: P02 | B3: Ветер — запрет работ на высоте | C3: ≥ 15 м/с | D3: № 109, п. 4 | E3: Сверено
A4: P03 | B4: Радиус ограждения при высоте работ | C4: ≤10 м → 4 м; ≤20 → 7; ≤50 → 10; ≤100 → 12,5; ≤150 → 20; ≤200 → 25; >200 → 30 | D4: № 109, п. 77 | E4: Сверено
A5: P04 | B5: Предметы на высоте с независимой страховкой | C5: > 10 кг | D5: № 109, п. 85 | E5: Сверено
A6: P05 | B6: Огневые работы — удаление от ЛВЖ/ВВ | C6: ≥ 50 м | D6: № 355, п. 32 | E6: Сверено
A7: P06 | B7: Ограждение траншей, котлованов | C7: ≥ 1 м или защитное покрытие | D7: № 355, п. 128 | E7: Сверено
A8: P07 | B8: Работа крана вблизи ВЛ — отдельный НД | C8: 30 м | D8: Правила ГПМ № 359 | E8: Сверить пункт
A9: P08 | B9: Глубина выемки без крепления по видам грунта | C9: — | D9: СН РК 1.03-05-2011 | E9: Сверить и заполнить
A10: P09 | B10: Тёплый период для правила N03 (Мангистауская обл.) | C10: — | D10: Параметр ОМГ | E10: Задать
A11: P10 | B11: Шкалы В, П и пороги зон риска | C11: — | D11: Стандарт КМГ / ОМГ | E11: Задать
A12: P11 | B12: Противопожарная служба для огневых работ на объектах ОМГ | C12: — | D12: Стандарт ОМГ | E12: Задать
... A15: P14 | B15: Порог Р для обязательной связи с разделом 5 (RA18) | C15: — | D15: Параметр ОМГ | E15: Задать

Sheet Источники
A1: Код | B1: Документ | C1: Ссылка
A2: № 344 | B2: Правила оформления и применения нарядов-допусков при производстве работ в условиях повышенной опасности, приказ МТСЗН РК от 28.08.2020 № 344 | C2: https://adilet.zan.kz/rus/docs/V2000021151
A3: № 355 | B3: Правила обеспечения ПБ для ОПО нефтяной и газовой отраслей, приказ МИР РК от 30.12.2014 № 355 (ред. приказа МЧС от 02.10.2025 № 434) | C3: https://adilet.zan.kz/rus/docs/V1400010250
A4: № 109 | B4: Правила по обеспечению безопасности и охраны труда при работе на высоте, приказ МТСЗН РК от 31.03.2022 № 109 | C4: https://adilet.zan.kz/rus/docs/V2200027349
A5: № 359 | B5: Правила обеспечения ПБ при эксплуатации грузоподъёмных механизмов, приказ МИР РК от 30.12.2014 № 359 | C5: https://adilet.zan.kz/rus/docs/V1400010332
A6: ППБ № 55 | B6: Правила пожарной безопасности, приказ МЧС РК от 21.02.2022 № 55 | C6: https://adilet.zan.kz/rus/docs/V2200026867
A7: V1400010238 | B7: Правила обеспечения ПБ для ОПО по подготовке и переработке газов (используется по аналогии, решение ОМГ) | C7: https://adilet.zan.kz/rus/docs/V1400010238
A8: СН РК 1.03-05-2011 | B8: Охрана труда и техника безопасности в строительстве (земляные работы — сверить) | C8: —
